<?xml version='1.0' encoding='utf-8'?>
<robot name="x500_arm2x_control">
  <!-- Source URDF SHA256: b8f46a3c5216b39dfa51f4560701b538045eed3552e38f578a0b2194e59bc918 -->
  <link name="base_link">
    <inertial>
      <origin xyz="-0.013121 0.00017397 -0.067418" rpy="0 0 0" />
      <mass value="1.8403" />
      <inertia ixx="0.019333" ixy="5.072E-05" ixz="0.0010586" iyy="0.02214" iyz="-4.352E-05" izz="0.028275" />
    </inertial>
  </link>
  <link name="link_1">
    <inertial>
      <origin xyz="-0.025459 0.17263 -0.00094115" rpy="0 0 0" />
      <mass value="0.15156" />
      <inertia ixx="0.00087586" ixy="0.0001761" ixz="-2.32E-06" iyy="9.027E-05" iyz="7.76E-06" izz="0.00092044" />
    </inertial>
  </link>
  <joint name="joint_1" type="revolute">
    <origin xyz="0 0.0002 -0.1503" rpy="-1.5708 0 3.1416" />
    <parent link="base_link" />
    <child link="link_1" />
    <axis xyz="0 0 1" />
    <limit lower="-2.6485" upper="2.6485" effort="5.24" velocity="6.28" />
  </joint>
  <link name="link_2">
    <inertial>
      <origin xyz="-0.039172 -0.18259 -0.00068453" rpy="0 0 0" />
      <mass value="0.14766" />
      <inertia ixx="0.0016083" ixy="-4.92E-05" ixz="-1.8E-07" iyy="4.02E-05" iyz="-8.08E-06" izz="0.0016046" />
    </inertial>
  </link>
  <joint name="joint_2" type="revolute">
    <origin xyz="-0.04123 0.2314 -0.0005" rpy="0 0 3.1416" />
    <parent link="link_1" />
    <child link="link_2" />
    <axis xyz="0 0 1" />
    <limit lower="0" upper="3.1415" effort="3.92" velocity="7.85" />
  </joint>
  <link name="link_3">
    <inertial>
      <origin xyz="0.0055284 -0.033186 -3.76E-06" rpy="0 0 0" />
      <mass value="0.0636" />
      <inertia ixx="2.011E-05" ixy="1.71E-06" ixz="0" iyy="1.802E-05" iyz="0" izz="2.34E-05" />
    </inertial>
  </link>
  <joint name="joint_3" type="revolute">
    <origin xyz="-0.04098 -0.2686 0" rpy="0 0 0" />
    <parent link="link_2" />
    <child link="link_3" />
    <axis xyz="0 0 1" />
    <limit lower="-2.6485" upper="2.6485" effort="2.75" velocity="4.71" />
  </joint>
  <link name="link_4">
    <inertial>
      <origin xyz="-8.08936229013e-05 -0.0013581756244 0.043125786869" rpy="0 0 0" />
      <mass value="0.15272" />
      <inertia ixx="0.000114699427694" ixy="1.57880455352e-06" ixz="1.62506217408e-07" iyy="0.000340738958485" iyz="-4.73876972285e-06" izz="0.000267101289269" />
    </inertial>
  </link>
  <joint name="joint_4" type="revolute">
    <origin xyz="0 -0.05189 0" rpy="1.5708 1.5708 0" />
    <parent link="link_3" />
    <child link="link_4" />
    <axis xyz="0 0 1" />
    <limit lower="-3.1415" upper="3.1415" effort="1.11" velocity="10.47" />
  </joint>
  <link name="ee_link" />
  <joint name="ee_fixed_joint" type="fixed">
    <origin xyz="0 0.008255 0.0643" rpy="0 0 0" />
    <parent link="link_4" />
    <child link="ee_link" />
  </joint>
</robot>
